Workbook
Name m: 'M stock'!$A$5:$BQ$271
Name p: 'p2'!$A$5:$BQ$271
Name PQ: PQ!$A$5:$BQ$271

Sheet Subject
B1: =VLOOKUP(C1,PQ!A6:B271,2,FALSE) -> VEN | C1: Venezuela, RB | H1: =IFERROR(B3+B4,"wrong") -> 2.0201373
A2: Period | B2: P | C2: Observe | D2: Economy | E2: Diagnosis | F2: Δ P % | G2: Q | H2: Δ Q | I2: Δ Q % | J2: PQ | K2: Δ PQ | L2: Δ PQ % | M2: Δ PQ % - Δ Q % | N2: test | O2: match? | P2: (Δ PQ % - Δ Q %) -Δ P % = Δ P x Δ Q (interaction) | Q2: ΔPQ | R2: Δ%PQ | S2: M | T2: ΔM % | U2: MV | V2: ΔMV % | W2: M(d.) | X2: ΔM(d.) % | Y2: V | Z2: Δ V % | AA2: MV(d.) | AB2: ΔMV(d.) | AC2: Δ%MV(d.) | AD2: PQ-MV(d.) (FAC) | AE2: MV(d.) + FAC | AF2: Δ MV(d.)+FAC % | AG2: Δ MV(d.)+FAC % - Δ Q % | AH2: Δ MV(d.)+FAC % - Δ M % | AI2: Δ MV(d.)+FAC % - Δ M % | AJ2: Δ MV(d.)+FAC % - Δ V % | AK2: test | AL2: match? | AM2: M_FAC | AN2: V_FAC
A3: 1960 | B3: =INDEX(p, MATCH($B$1, 'p2'!$B$5:$B$271, 0), MATCH(A3, 'p2'!$A$5:$BQ$5, 0)) -> 1 | G3: =J3/B3 -> 7.6639383e+09 | H3: =G3-G2 -> #VALUE! | I3: =H3-H2 -> #VALUE! | J3: =INDEX(PQ, MATCH($B$1, PQ!$B$5:$B$271, 0), MATCH(A3, PQ!$A$5:$BQ$5, 0)) -> 7.6639383e+09 | K3: =J3-J2 -> #VALUE! | L3: =(K3-K2)/K2 -> #VALUE! | M3: =L3-I3 -> #VALUE! | S3: =INDEX(m, MATCH($B$1, 'M stock'!$B$5:$B$271, 0), MATCH(A3, 'M stock'!$A$5:$BQ$5, 0)) -> 1.5718373e+09 | U3: =S3*Y3 -> 7.6639383e+09 | W3: =S3/B3 -> 1.5718373e+09 | Y3: =J3/S3 -> 4.8757835 | AA3: =W3*Y3 -> 7.6639383e+09 | AD3: =J3-AA3 -> 0 | AE3: =AA3+AD3 -> 7.6639383e+09 | AG3: =AF3-I3 -> #VALUE! | AH3: =AF3-T4 -> -0.011700369 | AI3: =AF3-X3 -> 0 | AJ3: =AF3-Z3 -> 0
A4: 1961 | B4: =INDEX(p, MATCH($B$1, 'p2'!$B$5:$B$271, 0), MATCH(A4, 'p2'!$A$5:$BQ$5, 0)) -> 1.0201373 | C4: =IF(B4>B3,"inflation",IF(B4<B3,"deflation","stable")) -> inflation | D4: =IF(I4>0,"expansive","contractive") -> expansive | E4: =IF(AND(C4="inflation",D4="expansive"),"inflationary expansion",IF(AND(C4="inflation",D4="contractive"),"stagflation",IF(AND(C4="deflation",D4="expansive"),"deflationary growth",IF(AND(C4="deflation",D4="contractive"),"recession",0)))) -> inflationary expansion | F4: =(B4-B3)/B3 -> 0.020137306 | G4: =J4/B4 -> 7.9080208e+09 | H4: =G4-G3 -> 2.440825e+08 | I4: =H4/G3 -> 0.031848181 | J4: =INDEX(PQ, MATCH($B$1, PQ!$B$5:$B$271, 0), MATCH(A4, PQ!$A$5:$BQ$5, 0)) -> 8.067267e+09 | K4: =J4-J3 -> 4.0332873e+08 | L4: =K4/J3 -> 0.052626823 | M4: =L4-I4 -> 0.020778642 | N4: =IF(L4>I4, "inflation",IF(L4<I4, "deflation","stable")) -> inflation | O4: =IFERROR(IF(N4=C4,1,0),"") -> 1 | P4: =M4-F4 -> 0.00064133656 | Q4: =J4-J3 -> 4.0332873e+08 | R4: =Q4/J3 -> 0.052626823 | S4: =INDEX(m, MATCH($B$1, 'M stock'!$B$5:$B$271, 0), MATCH(A4, 'M stock'!$A$5:$BQ$5, 0)) -> 1.5902284e+09 | T4: =(S4-S3)/S3 -> 0.011700369 | U4: =S4*Y4 -> 8.067267e+09 | V4: =(U4-U3)/U3 -> 0.052626823 | W4: =S4/B4 -> 1.5588376e+09 | X4: =(W4-W3)/W3 -> -0.0082703932 | Y4: =J4/S4 -> 5.0730242 | Z4: =(Y4-Y3)/Y3 -> 0.040453138 | AA4: =W4*Y4 -> 7.9080208e+09 | AB4: =AA4-AA3 -> 2.440825e+08 | AC4: =AB4/AA3 -> 0.031848181 | AD4: =J4-AA4 -> 1.5924623e+08 | AE4: =AA4+AD4 -> 8.067267e+09 | AF4: =(AE4-AE3)/AE3 -> 0.052626823 | AG4: =AF4-I4 -> 0.020778642 | AH4: =AF4-T5 -> 0.03699529 | AI4: =AF4-X4 -> 0.060897217 | AJ4: =AF4-Z4 -> 0.012173686 | AK4: =IF(AG4>0, "inflation",IF(AG4<0,"deflation","stable")) -> inflation | AL4: =IFERROR(IF(AK4=C4,1,0),"") -> 1 | AM4: =AD4/AN4 -> 31390789 | AN4: =Y4 -> 5.0730242
A5: 1962 | B5: =INDEX(p, MATCH($B$1, 'p2'!$B$5:$B$271, 0), MATCH(A5, 'p2'!$A$5:$BQ$5, 0)) -> 1.0269218 | C5: =IF(B5>B4,"inflation",IF(B5<B4,"deflation","stable")) -> inflation | D5: =IF(I5>0,"expansive","contractive") -> expansive | E5: =IF(AND(C5="inflation",D5="expansive"),"inflationary expansion",IF(AND(C5="inflation",D5="contractive"),"stagflation",IF(AND(C5="deflation",D5="expansive"),"deflationary growth",IF(AND(C5="deflation",D5="contractive"),"recession",0)))) -> inflationary expansion | F5: =(B5-B4)/B4 -> 0.0066505414 | G5: =J5/B5 -> 8.583234e+09 | H5: =G5-G4 -> 6.7521322e+08 | I5: =H5/G4 -> 0.085383339 | J5: =INDEX(PQ, MATCH($B$1, PQ!$B$5:$B$271, 0), MATCH(A5, PQ!$A$5:$BQ$5, 0)) -> 8.8143099e+09 | K5: =J5-J4 -> 7.4704285e+08 | L5: =K5/J4 -> 0.092601726 | M5: =L5-I5 -> 0.0072183868 | N5: =IF(L5>I5, "inflation",IF(L5<I5, "deflation","stable")) -> inflation | O5: =IFERROR(IF(N5=C5,1,0),"") -> 1 | P5: =M5-F5 -> 0.00056784543 | Q5: =J5-J4 -> 7.4704285e+08 | R5: =Q5/J4 -> 0.092601726 | S5: =INDEX(m, MATCH($B$1, 'M stock'!$B$5:$B$271, 0), MATCH(A5, 'M stock'!$A$5:$BQ$5, 0)) -> 1.6150861e+09 | T5: =(S5-S4)/S4 -> 0.015631534 | U5: =S5*Y5 -> 8.8143099e+09 | V5: =(U5-U4)/U4 -> 0.092601726 | W5: =S5/B5 -> 1.572745e+09 | X5: =(W5-W4)/W4 -> 0.0089216586 | Y5: =J5/S5 -> 5.4574861 | Z5: =(Y5-Y4)/Y4 -> 0.075785548 | AA5: =W5*Y5 -> 8.583234e+09 | AB5: =AA5-AA4 -> 6.7521322e+08 | AC5: =AB5/AA4 -> 0.085383339 | AD5: =J5-AA5 -> 2.3107586e+08 | AE5: =AA5+AD5 -> 8.8143099e+09 | AF5: =(AE5-AE4)/AE4 -> 0.092601726 | AG5: =AF5-I5 -> 0.0072183868 | AH5: =AF5-T6 -> -0.069856684 | AI5: =AF5-X5 -> 0.083680068 | AJ5: =AF5-Z5 -> 0.016816178 | AK5: =IF(AG5>0, "inflation",IF(AG5<0,"deflation","stable")) -> inflation | AL5: =IFERROR(IF(AK5=C5,1,0),"") -> 1 | AM5: =AD5/AN5 -> 42341081 | AN5: =Y5 -> 5.4574861
A6: 1963 | B6: =INDEX(p, MATCH($B$1, 'p2'!$B$5:$B$271, 0), MATCH(A6, 'p2'!$A$5:$BQ$5, 0)) -> 1.0774446 | C6: =IF(B6>B5,"inflation",IF(B6<B5,"deflation","stable")) -> inflation | D6: =IF(I6>0,"expansive","contractive") -> expansive | E6: =IF(AND(C6="inflation",D6="expansive"),"inflationary expansion",IF(AND(C6="inflation",D6="contractive"),"stagflation",IF(AND(C6="deflation",D6="expansive"),"deflationary growth",IF(AND(C6="deflation",D6="contractive"),"recession",0)))) -> inflationary expansion | F6: =(B6-B5)/B5 -> 0.049198298 | G6: =J6/B6 -> 8.9180618e+09 | H6: =G6-G5 -> 3.3482777e+08 | I6: =H6/G5 -> 0.039009512 | J6: =INDEX(PQ, MATCH($B$1, PQ!$B$5:$B$271, 0), MATCH(A6, PQ!$A$5:$BQ$5, 0)) -> 9.6087173e+09 | K6: =J6-J5 -> 7.944074e+08 | L6: =K6/J5 -> 0.090127011 | M6: =L6-I6 -> 0.051117499 | N6: =IF(L6>I6, "inflation",IF(L6<I6, "deflation","stable")) -> inflation | O6: =IFERROR(IF(N6=C6,1,0),"") -> 1 | P6: =M6-F6 -> 0.0019192016 | Q6: =J6-J5 -> 7.944074e+08 | R6: =Q6/J5 -> 0.090127011 | S6: =INDEX(m, MATCH($B$1, 'M stock'!$B$5:$B$271, 0), MATCH(A6, 'M stock'!$A$5:$BQ$5, 0)) -> 1.8774704e+09 | T6: =(S6-S5)/S5 -> 0.16245841 | U6: =S6*Y6 -> 9.6087173e+09 | V6: =(U6-U5)/U5 -> 0.090127011 | W6: =S6/B6 -> 1.7425216e+09 | X6: =(W6-W5)/W5 -> 0.1079492 | Y6: =J6/S6 -> 5.1179062 | Z6: =(Y6-Y5)/Y5 -> -0.062222785 | AA6: =W6*Y6 -> 8.9180618e+09 | AB6: =AA6-AA5 -> 3.3482777e+08 | AC6: =AB6/AA5 -> 0.039009512 | AD6: =J6-AA6 -> 6.906555e+08 | AE6: =AA6+AD6 -> 9.6087173e+09 | AF6: =(AE6-AE5)/AE5 -> 0.090127011 | AG6: =AF6-I6 -> 0.051117499 | AH6: =AF6-T7 -> 0.19506109 | AI6: =AF6-X6 -> -0.017822185 | AJ6: =AF6-Z6 -> 0.1523498 | AK6: =IF(AG6>0, "inflation",IF(AG6<0,"deflation","stable")) -> inflation | AL6: =IFERROR(IF(AK6=C6,1,0),"") -> 1 | AM6: =AD6/AN6 -> 1.3494884e+08 | AN6: =Y6 -> 5.1179062
A7: 1964 | B7: =INDEX(p, MATCH($B$1, 'p2'!$B$5:$B$271, 0), MATCH(A7, 'p2'!$A$5:$BQ$5, 0)) -> 1.0734957 | C7: =IF(B7>B6,"inflation",IF(B7<B6,"deflation","stable")) -> deflation | D7: =IF(I7>0,"expansive","contractive") -> contractive | E7: =IF(AND(C7="inflation",D7="expansive"),"inflationary expansion",IF(AND(C7="inflation",D7="contractive"),"stagflation",IF(AND(C7="deflation",D7="expansive"),"deflationary growth",IF(AND(C7="deflation",D7="contractive"),"recession",0)))) -> recession | F7: =(B7-B6)/B6 -> -0.0036650286 | G7: =J7/B7 -> 7.6315291e+09 | H7: =G7-G6 -> -1.2865326e+09 | I7: =H7/G6 -> -0.14426146 | J7: =INDEX(PQ, MATCH($B$1, PQ!$B$5:$B$271, 0), MATCH(A7, PQ!$A$5:$BQ$5, 0)) -> 8.1924138e+09 | K7: =J7-J6 -> -1.4163035e+09 | L7: =K7/J6 -> -0.14739777 | M7: =L7-I7 -> -0.0031363062 | N7: =IF(L7>I7, "inflation",IF(L7<I7, "deflation","stable")) -> deflation | O7: =IFERROR(IF(N7=C7,1,0),"") -> 1 | P7: =M7-F7 -> 0.00052872239 | Q7: =J7-J6 -> -1.4163035e+09 | R7: =Q7/J6 -> -0.14739777 | S7: =INDEX(m, MATCH($B$1, 'M stock'!$B$5:$B$271, 0), MATCH(A7, 'M stock'!$A$5:$BQ$5, 0)) -> 1.6804598e+09 | T7: =(S7-S6)/S6 -> -0.10493408 | U7: =S7*Y7 -> 8.1924138e+09 | V7: =(U7-U6)/U6 -> -0.14739777 | W7: =S7/B7 -> 1.5654089e+09 | X7: =(W7-W6)/W6 -> -0.10164157 | Y7: =J7/S7 -> 4.8751026 | Z7: =(Y7-Y6)/Y6 -> -0.047441971 | AA7: =W7*Y7 -> 7.6315291e+09 | AB7: =AA7-AA6 -> -1.2865326e+09 | AC7: =AB7/AA6 -> -0.14426146 | AD7: =J7-AA7 -> 5.6088464e+08 | AE7: =AA7+AD7 -> 8.1924138e+09 | AF7: =(AE7-AE6)/AE6 -> -0.14739777 | AG7: =AF7-I7 -> -0.0031363062 | AH7: =AF7-T8 -> -0.1928524 | AI7: =AF7-X7 -> -0.0457562 | AJ7: =AF7-Z7 -> -0.099955799 | AK7: =IF(AG7>0, "inflation",IF(AG7<0,"deflation","stable")) -> deflation | AL7: =IFERROR(IF(AK7=C7,1,0),"") -> 1 | AM7: =AD7/AN7 -> 1.1505084e+08 | AN7: =Y7 -> 4.8751026
A8: 1965 | B8: =INDEX(p, MATCH($B$1, 'p2'!$B$5:$B$271, 0), MATCH(A8, 'p2'!$A$5:$BQ$5, 0)) -> 1.0967606 | C8: =IF(B8>B7,"inflation",IF(B8<B7,"deflation","stable")) -> inflation | D8: =IF(I8>0,"expansive","contractive") -> expansive | E8: =IF(AND(C8="inflation",D8="expansive"),"inflationary expansion",IF(AND(C8="inflation",D8="contractive"),"stagflation",IF(AND(C8="deflation",D8="expansive"),"deflationary growth",IF(AND(C8="deflation",D8="contractive"),"recession",0)))) -> inflationary expansion | F8: =(B8-B7)/B7 -> 0.021672088 | G8: =J8/B8 -> 7.6842455e+09 | H8: =G8-G7 -> 52716399 | I8: =H8/G7 -> 0.0069077111 | J8: =INDEX(PQ, MATCH($B$1, PQ!$B$5:$B$271, 0), MATCH(A8, PQ!$A$5:$BQ$5, 0)) -> 8.4277778e+09 | K8: =J8-J7 -> 2.3536398e+08 | L8: =K8/J7 -> 0.028729504 | M8: =L8-I8 -> 0.021821793 | N8: =IF(L8>I8, "inflation",IF(L8<I8, "deflation","stable")) -> inflation | O8: =IFERROR(IF(N8=C8,1,0),"") -> 1 | P8: =M8-F8 -> 0.00014970453 | Q8: =J8-J7 -> 2.3536398e+08 | R8: =Q8/J7 -> 0.028729504 | S8: =INDEX(m, MATCH($B$1, 'M stock'!$B$5:$B$271, 0), MATCH(A8, 'M stock'!$A$5:$BQ$5, 0)) -> 1.7568444e+09 | T8: =(S8-S7)/S7 -> 0.045454628 | U8: =S8*Y8 -> 8.4277778e+09 | V8: =(U8-U7)/U7 -> 0.028729504 | W8: =S8/B8 -> 1.6018486e+09 | X8: =(W8-W7)/W7 -> 0.023278056 | Y8: =J8/S8 -> 4.797111 | Z8: =(Y8-Y7)/Y7 -> -0.015997944 | AA8: =W8*Y8 -> 7.6842455e+09 | AB8: =AA8-AA7 -> 52716399 | AC8: =AB8/AA7 -> 0.0069077111 | AD8: =J8-AA8 -> 7.4353223e+08 | AE8: =AA8+AD8 -> 8.4277778e+09 | AF8: =(AE8-AE7)/AE7 -> 0.028729504 | AG8: =AF8-I8 -> 0.021821793 | AH8: =AF8-T9 -> 0.029058376 | AI8: =AF8-X8 -> 0.0054514481 | AJ8: =AF8-Z8 -> 0.044727448 | AK8: =IF(AG8>0, "inflation",IF(AG8<0,"deflation","stable")) -> inflation | AL8: =IFERROR(IF(AK8=C8,1,0),"") -> 1 | AM8: =AD8/AN8 -> 1.5499584e+08 | AN8: =Y8 -> 4.797111
A9: 1966 | B9: =INDEX(p, MATCH($B$1, 'p2'!$B$5:$B$271, 0), MATCH(A9, 'p2'!$A$5:$BQ$5, 0)) -> 1.1257691 | C9: =IF(B9>B8,"inflation",IF(B9<B8,"deflation","stable")) -> inflation | D9: =IF(I9>0,"expansive","contractive") -> expansive | E9: =IF(AND(C9="inflation",D9="expansive"),"inflationary expansion",IF(AND(C9="inflation",D9="contractive"),"stagflation",IF(AND(C9="deflation",D9="expansive"),"deflationary growth",IF(AND(C9="deflation",D9="contractive"),"recession",0)))) -> inflationary expansion | F9: =(B9-B8)/B8 -> 0.026449268 | G9: =J9/B9 -> 7.8002969e+09 | H9: =G9-G8 -> 1.1605133e+08 | I9: =H9/G8 -> 0.015102501 | J9: =INDEX(PQ, MATCH($B$1, PQ!$B$5:$B$271, 0), MATCH(A9, PQ!$A$5:$BQ$5, 0)) -> 8.7813333e+09 | K9: =J9-J8 -> 3.5355556e+08 | L9: =K9/J8 -> 0.04195122 | M9: =L9-I9 -> 0.026848718 | N9: =IF(L9>I9, "inflation",IF(L9<I9, "deflation","stable")) -> inflation | O9: =IFERROR(IF(N9=C9,1,0),"") -> 1 | P9: =M9-F9 -> 0.0003994501 | Q9: =J9-J8 -> 3.5355556e+08 | R9: =Q9/J8 -> 0.04195122 | S9: =INDEX(m, MATCH($B$1, 'M stock'!$B$5:$B$271, 0), MATCH(A9, 'M stock'!$A$5:$BQ$5, 0)) -> 1.7562667e+09 | T9: =(S9-S8)/S8 -> -0.00032887247 | U9: =S9*Y9 -> 8.7813333e+09 | V9: =(U9-U8)/U8 -> 0.04195122 | W9: =S9/B9 -> 1.5600594e+09 | X9: =(W9-W8)/W8 -> -0.026088129 | Y9: =J9/S9 -> 5 | Z9: =(Y9-Y8)/Y8 -> 0.042294001 | AA9: =W9*Y9 -> 7.8002969e+09 | AB9: =AA9-AA8 -> 1.1605133e+08 | AC9: =AB9/AA8 -> 0.015102501 | AD9: =J9-AA9 -> 9.8103646e+08 | AE9: =AA9+AD9 -> 8.7813333e+09 | AF9: =(AE9-AE8)/AE8 -> 0.04195122 | AG9: =AF9-I9 -> 0.026848718 | AH9: =AF9-T10 -> -0.093512896 | AI9: =AF9-X9 -> 0.068039348 | AJ9: =AF9-Z9 -> -0.00034278181 | AK9: =IF(AG9>0, "inflation",IF(AG9<0,"deflation","stable")) -> inflation | AL9: =IFERROR(IF(AK9=C9,1,0),"") -> 1 | AM9: =AD9/AN9 -> 1.9620729e+08 | AN9: =Y9 -> 5
A10: 1967 | B10: =INDEX(p, MATCH($B$1, 'p2'!$B$5:$B$271, 0), MATCH(A10, 'p2'!$A$5:$BQ$5, 0)) -> 1.1531729 | C10: =IF(B10>B9,"inflation",IF(B10<B9,"deflation","stable")) -> inflation | D10: =IF(I10>0,"expansive","contractive") -> expansive | E10: =IF(AND(C10="inflation",D10="expansive"),"inflationary expansion",IF(AND(C10="inflation",D10="contractive"),"stagflation",IF(AND(C10="deflation",D10="expansive"),"deflationary growth",IF(AND(C10="deflation",D10="contractive"),"recession",0)))) -> inflationary expansion | F10: =(B10-B9)/B9 -> 0.024342268 | G10: =J10/B10 -> 8.0213471e+09 | H10: =G10-G9 -> 2.210502e+08 | I10: =H10/G9 -> 0.02833869 | J10: =INDEX(PQ, MATCH($B$1, PQ!$B$5:$B$271, 0), MATCH(A10, PQ!$A$5:$BQ$5, 0)) -> 9250000000 | K10: =J10-J9 -> 4.6866667e+08 | L10: =K10/J9 -> 0.053370787 | M10: =L10-I10 -> 0.025032096 | N10: =IF(L10>I10, "inflation",IF(L10<I10, "deflation","stable")) -> inflation | O10: =IFERROR(IF(N10=C10,1,0),"") -> 1 | P10: =M10-F10 -> 0.000689828 | Q10: =J10-J9 -> 4.6866667e+08 | R10: =Q10/J9 -> 0.053370787 | S10: =INDEX(m, MATCH($B$1, 'M stock'!$B$5:$B$271, 0), MATCH(A10, 'M stock'!$A$5:$BQ$5, 0)) -> 1.9941778e+09 | T10: =(S10-S9)/S9 -> 0.13546412 | U10: =S10*Y10 -> 9250000000 | V10: =(U10-U9)/U9 -> 0.053370787 | W10: =S10/B10 -> 1.7292964e+09 | X10: =(W10-W9)/W9 -> 0.10848117 | Y10: =J10/S10 -> 4.6385032 | Z10: =(Y10-Y9)/Y9 -> -0.07229936 | AA10: =W10*Y10 -> 8.0213471e+09 | AB10: =AA10-AA9 -> 2.210502e+08 | AC10: =AB10/AA9 -> 0.02833869 | AD10: =J10-AA10 -> 1.2286529e+09 | AE10: =AA10+AD10 -> 9250000000 | AF10: =(AE10-AE9)/AE9 -> 0.053370787 | AG10: =AF10-I10 -> 0.025032096 | AH10: =AF10-T11 -> -0.041940007 | AI10: =AF10-X10 -> -0.055110383 | AJ10: =AF10-Z10 -> 0.12567015 | AK10: =IF(AG10>0, "inflation",IF(AG10<0,"deflation","stable")) -> inflation | AL10: =IFERROR(IF(AK10=C10,1,0),"") -> 1 | AM10: =AD10/AN10 -> 2.6488134e+08 | AN10: =Y10 -> 4.6385032
A11: 1968 | B11: =INDEX(p, MATCH($B$1, 'p2'!$B$5:$B$271, 0), MATCH(A11, 'p2'!$A$5:$BQ$5, 0)) -> 1.1654553 | C11: =IF(B11>B10,"inflation",IF(B11<B10,"deflation","stable")) -> inflation | D11: =IF(I11>0,"expansive","contractive") -> expansive | E11: =IF(AND(C11="inflation",D11="expansive"),"inflationary expansion",IF(AND(C11="inflation",D11="contractive"),"stagflation",IF(AND(C11="deflation",D11="expansive"),"deflationary growth",IF(AND(C11="deflation",D11="contractive"),"recession",0)))) -> inflationary expansion | F11: =(B11-B10)/B10 -> 0.01065099 | G11: =J11/B11 -> 8.609892e+09 | H11: =G11-G10 -> 5.885449e+08 | I11: =H11/G10 -> 0.073372327 | J11: =INDEX(PQ, MATCH($B$1, PQ!$B$5:$B$271, 0), MATCH(A11, PQ!$A$5:$BQ$5, 0)) -> 1.0034444e+10 | K11: =J11-J10 -> 7.8444444e+08 | L11: =K11/J10 -> 0.084804805 | M11: =L11-I11 -> 0.011432478 | N11: =IF(L11>I11, "inflation",IF(L11<I11, "deflation","stable")) -> inflation | O11: =IFERROR(IF(N11=C11,1,0),"") -> 1 | P11: =M11-F11 -> 0.00078148794 | Q11: =J11-J10 -> 7.8444444e+08 | R11: =Q11/J10 -> 0.084804805 | S11: =INDEX(m, MATCH($B$1, 'M stock'!$B$5:$B$271, 0), MATCH(A11, 'M stock'!$A$5:$BQ$5, 0)) -> 2.1842444e+09 | T11: =(S11-S10)/S10 -> 0.095310794 | U11: =S11*Y11 -> 1.0034444e+10 | V11: =(U11-U10)/U10 -> 0.084804805 | W11: =S11/B11 -> 1.8741554e+09 | X11: =(W11-W10)/W10 -> 0.083767596 | Y11: =J11/S11 -> 4.5940117 | Z11: =(Y11-Y10)/Y10 -> -0.0095917879 | AA11: =W11*Y11 -> 8.609892e+09 | AB11: =AA11-AA10 -> 5.885449e+08 | AC11: =AB11/AA10 -> 0.073372327 | AD11: =J11-AA11 -> 1.4245525e+09 | AE11: =AA11+AD11 -> 1.0034444e+10 | AF11: =(AE11-AE10)/AE10 -> 0.084804805 | AG11: =AF11-I11 -> 0.011432478 | AH11: =AF11-T12 -> -0.02387249 | AI11: =AF11-X11 -> 0.0010372093 | AJ11: =AF11-Z11 -> 0.094396593 | AK11: =IF(AG11>0, "inflation",IF(AG11<0,"deflation","stable")) -> inflation | AL11: =IFERROR(IF(AK11=C11,1,0),"") -> 1 | AM11: =AD11/AN11 -> 3.10089e+08 | AN11: =Y11 -> 4.5940117
A12: 1969 | B12: =INDEX(p, MATCH($B$1, 'p2'!$B$5:$B$271, 0), MATCH(A12, 'p2'!$A$5:$BQ$5, 0)) -> 1.1861942 | C12: =IF(B12>B11,"inflation",IF(B12<B11,"deflation","stable")) -> inflation | D12: =IF(I12>0,"expansive","contractive") -> expansive | E12: =IF(AND(C12="inflation",D12="expansive"),"inflationary expansion",IF(AND(C12="inflation",D12="contractive"),"stagflation",IF(AND(C12="deflation",D12="expansive"),"deflationary growth",IF(AND(C12="deflation",D12="contractive"),"recession",0)))) -> inflationary expansion | F12: =(B12-B11)/B11 -> 0.017794618 | G12: =J12/B12 -> 8.670681e+09 | H12: =G12-G11 -> 60789005 | I12: =H12/G11 -> 0.007060368 | J12: =INDEX(PQ, MATCH($B$1, PQ!$B$5:$B$271, 0), MATCH(A12, PQ!$A$5:$BQ$5, 0)) -> 1.0285111e+10 | K12: =J12-J11 -> 2.5066667e+08 | L12: =K12/J11 -> 0.024980622 | M12: =L12-I12 -> 0.017920254 | N12: =IF(L12>I12, "inflation",IF(L12<I12, "deflation","stable")) -> inflation | O12: =IFERROR(IF(N12=C12,1,0),"") -> 1 | P12: =M12-F12 -> 0.00012563655 | Q12: =J12-J11 -> 2.5066667e+08 | R12: =Q12/J11 -> 0.024980622 | S12: =INDEX(m, MATCH($B$1, 'M stock'!$B$5:$B$271, 0), MATCH(A12, 'M stock'!$A$5:$BQ$5, 0)) -> 2.4216222e+09 | T12: =(S12-S11)/S11 -> 0.10867729 | U12: =S12*Y12 -> 1.0285111e+10 | V12: =(U12-U11)/U11 -> 0.024980622 | W12: =S12/B12 -> 2.0415058e+09 | X12: =(W12-W11)/W11 -> 0.089293729 | Y12: =J12/S12 -> 4.2471988 | Z12: =(Y12-Y11)/Y11 -> -0.075492366 | AA12: =W12*Y12 -> 8.670681e+09 | AB12: =AA12-AA11 -> 60789005 | AC12: =AB12/AA11 -> 0.007060368 | AD12: =J12-AA12 -> 1.6144301e+09 | AE12: =AA12+AD12 -> 1.0285111e+10 | AF12: =(AE12-AE11)/AE11 -> 0.024980622 | AG12: =AF12-I12 -> 0.017920254 | AH12: =AF12-T13 -> -0.052515638 | AI12: =AF12-X12 -> -0.064313107 | AJ12: =AF12-Z12 -> 0.10047299 | AK12: =IF(AG12>0, "inflation",IF(AG12<0,"deflation","stable")) -> inflation | AL12: =IFERROR(IF(AK12=C12,1,0),"") -> 1 | AM12: =AD12/AN12 -> 3.8011645e+08 | AN12: =Y12 -> 4.2471988
A13: 1970 | B13: =INDEX(p, MATCH($B$1, 'p2'!$B$5:$B$271, 0), MATCH(A13, 'p2'!$A$5:$BQ$5, 0)) -> 1.2378916 | C13: =IF(B13>B12,"inflation",IF(B13<B12,"deflation","stable")) -> inflation | D13: =IF(I13>0,"expansive","contractive") -> expansive | E13: =IF(AND(C13="inflation",D13="expansive"),"inflationary expansion",IF(AND(C13="inflation",D13="contractive"),"stagflation",IF(AND(C13="deflation",D13="expansive"),"deflationary growth",IF(AND(C13="deflation",D13="contractive"),"recession",0)))) -> inflationary expansion | F13: =(B13-B12)/B12 -> 0.043582632 | G13: =J13/B13 -> 9.3393565e+09 | H13: =G13-G12 -> 6.6867549e+08 | I13: =H13/G12 -> 0.077119144 | J13: =INDEX(PQ, MATCH($B$1, PQ!$B$5:$B$271, 0), MATCH(A13, PQ!$A$5:$BQ$5, 0)) -> 1.1561111e+10 | K13: =J13-J12 -> 1276000000 | L13: =K13/J12 -> 0.12406283 | M13: =L13-I13 -> 0.046943687 | N13: =IF(L13>I13, "inflation",IF(L13<I13, "deflation","stable")) -> inflation | O13: =IFERROR(IF(N13=C13,1,0),"") -> 1 | P13: =M13-F13 -> 0.0033610552 | Q13: =J13-J12 -> 1276000000 | R13: =Q13/J12 -> 0.12406283 | S13: =INDEX(m, MATCH($B$1, 'M stock'!$B$5:$B$271, 0), MATCH(A13, 'M stock'!$A$5:$BQ$5, 0)) -> 2.6092889e+09 | T13: =(S13-S12)/S12 -> 0.077496261 | U13: =S13*Y13 -> 1.1561111e+10 | V13: =(U13-U12)/U12 -> 0.12406283 | W13: =S13/B13 -> 2.1078492e+09 | X13: =(W13-W12)/W12 -> 0.03249731 | Y13: =J13/S13 -> 4.4307517 | Z13: =(Y13-Y12)/Y12 -> 0.043217385 | AA13: =W13*Y13 -> 9.3393565e+09 | AB13: =AA13-AA12 -> 6.6867549e+08 | AC13: =AB13/AA12 -> 0.077119144 | AD13: =J13-AA13 -> 2.2217546e+09 | AE13: =AA13+AD13 -> 1.1561111e+10 | AF13: =(AE13-AE12)/AE12 -> 0.12406283 | AG13: =AF13-I13 -> 0.046943687 | AH13: =AF13-T14 -> -0.069749021 | AI13: =AF13-X13 -> 0.09156552 | AJ13: =AF13-Z13 -> 0.080845446 | AK13: =IF(AG13>0, "inflation",IF(AG13<0,"deflation","stable")) -> inflation | AL13: =IFERROR(IF(AK13=C13,1,0),"") -> 1 | AM13: =AD13/AN13 -> 5.0143967e+08 | AN13: =Y13 -> 4.4307517
A14: 1971 | B14: =INDEX(p, MATCH($B$1, 'p2'!$B$5:$B$271, 0), MATCH(A14, 'p2'!$A$5:$BQ$5, 0)) -> 1.339803 | C14: =IF(B14>B13,"inflation",IF(B14<B13,"deflation","stable")) -> inflation | D14: =IF(I14>0,"expansive","contractive") -> expansive | E14: =IF(AND(C14="inflation",D14="expansive"),"inflationary expansion",IF(AND(C14="inflation",D14="contractive"),"stagflation",IF(AND(C14="deflation",D14="expansive"),"deflationary growth",IF(AND(C14="deflation",D14="contractive"),"recession",0)))) -> inflationary expansion | F14: =(B14-B13)/B13 -> 0.082326576 | G14: =J14/B14 -> 9.6929108e+09 | H14: =G14-G13 -> 3.535543e+08 | I14: =H14/G13 -> 0.037856387 | J14: =INDEX(PQ, MATCH($B$1, PQ!$B$5:$B$271, 0), MATCH(A14, PQ!$A$5:$BQ$5, 0)) -> 1.2986591e+10 | K14: =J14-J13 -> 1.4254798e+09 | L14: =K14/J13 -> 0.12329955 | M14: =L14-I14 -> 0.085443163 | N14: =IF(L14>I14, "inflation",IF(L14<I14, "deflation","stable")) -> inflation | O14: =IFERROR(IF(N14=C14,1,0),"") -> 1 | P14: =M14-F14 -> 0.0031165867 | Q14: =J14-J13 -> 1.4254798e+09 | R14: =Q14/J13 -> 0.12329955 | S14: =INDEX(m, MATCH($B$1, 'M stock'!$B$5:$B$271, 0), MATCH(A14, 'M stock'!$A$5:$BQ$5, 0)) -> 3.115e+09 | T14: =(S14-S13)/S13 -> 0.19381185 | U14: =S14*Y14 -> 1.2986591e+10 | V14: =(U14-U13)/U13 -> 0.12329955 | W14: =S14/B14 -> 2.3249687e+09 | X14: =(W14-W13)/W13 -> 0.10300521 | Y14: =J14/S14 -> 4.1690501 | Z14: =(Y14-Y13)/Y13 -> -0.059064836 | AA14: =W14*Y14 -> 9.6929108e+09 | AB14: =AA14-AA13 -> 3.535543e+08 | AC14: =AB14/AA13 -> 0.037856387 | AD14: =J14-AA14 -> 3.2936801e+09 | AE14: =AA14+AD14 -> 1.2986591e+10 | AF14: =(AE14-AE13)/AE13 -> 0.12329955 | AG14: =AF14-I14 -> 0.085443163 | AH14: =AF14-T15 -> -0.073621506 | AI14: =AF14-X14 -> 0.02029434 | AJ14: =AF14-Z14 -> 0.18236439 | AK14: =IF(AG14>0, "inflation",IF(AG14<0,"deflation","stable")) -> inflation | AL14: =IFERROR(IF(AK14=C14,1,0),"") -> 1 | AM14: =AD14/AN14 -> 7.9003133e+08 | AN14: =Y14 -> 4.1690501
A15: 1972 | B15: =INDEX(p, MATCH($B$1, 'p2'!$B$5:$B$271, 0), MATCH(A15, 'p2'!$A$5:$BQ$5, 0)) -> 1.4237923 | C15: =IF(B15>B14,"inflation",IF(B15<B14,"deflation","stable")) -> inflation | D15: =IF(I15>0,"expansive","contractive") -> expansive | E15: =IF(AND(C15="inflation",D15="expansive"),"inflationary expansion",IF(AND(C15="inflation",D15="contractive"),"stagflation",IF(AND(C15="deflation",D15="expansive"),"deflationary growth",IF(AND(C15="deflation",D15="contractive"),"recession",0)))) -> inflationary expansion | F15: =(B15-B14)/B14 -> 0.062687768 | G15: =J15/B15 -> 9.8172519e+09 | H15: =G15-G14 -> 1.2434115e+08 | I15: =H15/G14 -> 0.01282805 | J15: =INDEX(PQ, MATCH($B$1, PQ!$B$5:$B$271, 0), MATCH(A15, PQ!$A$5:$BQ$5, 0)) -> 1.3977727e+10 | K15: =J15-J14 -> 9.9113636e+08 | L15: =K15/J14 -> 0.07631998 | M15: =L15-I15 -> 0.06349193 | N15: =IF(L15>I15, "inflation",IF(L15<I15, "deflation","stable")) -> inflation | O15: =IFERROR(IF(N15=C15,1,0),"") -> 1 | P15: =M15-F15 -> 0.00080416185 | Q15: =J15-J14 -> 9.9113636e+08 | R15: =Q15/J14 -> 0.07631998 | S15: =INDEX(m, MATCH($B$1, 'M stock'!$B$5:$B$271, 0), MATCH(A15, 'M stock'!$A$5:$BQ$5, 0)) -> 3.7284091e+09 | T15: =(S15-S14)/S14 -> 0.19692106 | U15: =S15*Y15 -> 1.3977727e+10 | V15: =(U15-U14)/U14 -> 0.07631998 | W15: =S15/B15 -> 2.6186468e+09 | X15: =(W15-W14)/W14 -> 0.12631489 | Y15: =J15/S15 -> 3.748979 | Z15: =(Y15-Y14)/Y14 -> -0.10075942 | AA15: =W15*Y15 -> 9.8172519e+09 | AB15: =AA15-AA14 -> 1.2434115e+08 | AC15: =AB15/AA14 -> 0.01282805 | AD15: =J15-AA15 -> 4.1604754e+09 | AE15: =AA15+AD15 -> 1.3977727e+10 | AF15: =(AE15-AE14)/AE14 -> 0.07631998 | AG15: =AF15-I15 -> 0.06349193 | AH15: =AF15-T16 -> -0.14828738 | AI15: =AF15-X15 -> -0.049994909 | AJ15: =AF15-Z15 -> 0.1770794 | AK15: =IF(AG15>0, "inflation",IF(AG15<0,"deflation","stable")) -> inflation | AL15: =IFERROR(IF(AK15=C15,1,0),"") -> 1 | AM15: =AD15/AN15 -> 1.1097623e+09 | AN15: =Y15 -> 3.748979
... A67: 2024 | B67: =INDEX(p, MATCH($B$1, 'p2'!$B$5:$B$271, 0), MATCH(A67, 'p2'!$A$5:$BQ$5, 0)) -> 0 | C67: =IF(B67>B66,"inflation",IF(B67<B66,"deflation","stable")) -> stable | D67: =IF(I67>0,"expansive","contractive") -> #DIV/0! | E67: =IF(AND(C67="inflation",D67="expansive"),"inflationary expansion",IF(AND(C67="inflation",D67="contractive"),"stagflation",IF(AND(C67="deflation",D67="expansive"),"deflationary growth",IF(AND(C67="deflation",D67="contractive"),"recession",0)))) -> #DIV/0! | F67: =(B67-B66)/B66 -> #DIV/0! | G67: =J67/B67 -> #DIV/0! | H67: =G67-G66 -> #DIV/0! | I67: =H67/G66 -> #DIV/0! | J67: =INDEX(PQ, MATCH($B$1, PQ!$B$5:$B$271, 0), MATCH(A67, PQ!$A$5:$BQ$5, 0)) -> 0 | K67: =J67-J66 -> 0 | L67: =K67/J66 -> #DIV/0! | M67: =L67-I67 -> #DIV/0! | N67: =IF(L67>I67, "inflation",IF(L67<I67, "deflation","stable")) -> #DIV/0! | O67: =IFERROR(IF(N67=C67,1,0),"") | P67: =M67-F67 -> #DIV/0! | Q67: =J67-J66 -> 0 | R67: =Q67/J66 -> #DIV/0! | S67: =INDEX(m, MATCH($B$1, 'M stock'!$B$5:$B$271, 0), MATCH(A67, 'M stock'!$A$5:$BQ$5, 0)) -> 0 | T67: =(S67-S66)/S66 -> #DIV/0! | U67: =S67*Y67 -> #DIV/0! | V67: =(U67-U66)/U66 -> #DIV/0! | W67: =S67/B67 -> #DIV/0! | X67: =(W67-W66)/W66 -> #DIV/0! | Y67: =J67/S67 -> #DIV/0! | Z67: =(Y67-Y66)/Y66 -> #DIV/0! | AA67: =W67*Y67 -> #DIV/0! | AB67: =AA67-AA66 -> #DIV/0! | AC67: =AB67/AA66 -> #DIV/0! | AD67: =J67-AA67 -> #DIV/0! | AE67: =AA67+AD67 -> #DIV/0! | AF67: =(AE67-AE66)/AE66 -> #DIV/0! | AG67: =AF67-I67 -> #DIV/0! | AH67: =AF67-T68 -> #DIV/0! | AI67: =AF67-X67 -> #DIV/0! | AJ67: =AF67-Z67 -> #DIV/0! | AK67: =IF(AG67>0, "inflation",IF(AG67<0,"deflation","stable")) -> #DIV/0! | AL67: =IFERROR(IF(AK67=C67,1,0),"") | AM67: =AD67/AN67 -> #DIV/0! | AN67: =Y67 -> #DIV/0!
N69: Economic Themal Dynamic Accuracy (Left Side PQ) | O69: =SUM(O4:O57)/COUNT(O4:O57) -> 1 | AK69: Economic Themal Dynamic Accuracy (Right Side MV+FAC) | AL69: =SUM(AL4:AL57)/COUNT(AL4:AL57) -> 1
N71: Matches | O71: =SUM(O3:O67) -> 54 | AK71: Matches | AL71: =SUM(AL3:AL67) -> 53
N72: Count | O72: =COUNT(O3:O67) -> 54 | AK72: Count | AL72: =COUNT(AL3:AL67) -> 53
A74: Source:
A75: World Bank
A76: https://data.worldbank.org/
A78: Broad Money (% of GDP)
A79: API_FM.LBL.BMNY.GD.ZS_DS2_en_csv_v2_123670
A80: Used to analyze monetary aggregates relative to GDP
A82: GDP Deflator (scaled to start meaningful P at 1)_
A83: API_NY.GDP.DEFL.ZS_DS2_en_csv_v2_124034
A84: Used to convert nominal GDP to real terms and track change in P over time
A86: GDP (current US$)
A87: API_NY.GDP.MKTP.CD_DS2_en_csv_v2_130122
A88: Core GDP series for nominal valuation
... A108: affirming the robustness of our own data sources and calculations.

Sheet USA History
A2: Period | B2: P | C2: Observe | D2: Economy | E2: Diagnosis | F2: Δ P % | G2: Q | H2: Δ Q | I2: Δ Q % | J2: PQ | K2: Δ PQ | L2: Δ PQ % | M2: Δ PQ % - Δ Q % | N2: test | O2: match? | P2: (Δ PQ % - Δ Q %) -Δ P % = Δ P x Δ Q (interaction) | Q2: ΔPQ | R2: Δ%PQ | S2: M | T2: ΔM % | U2: MV | V2: ΔMV % | W2: M(d.) | X2: ΔM(d.) % | Y2: V | Z2: Δ V % | AA2: MV(d.) | AB2: ΔMV(d.) | AC2: Δ%MV(d.) | AD2: PQ-MV(d.) (FAC) | AE2: MV(d.) + FAC | AF2: Δ MV(d.)+FAC % | AG2: Δ MV(d.)+FAC % - Δ Q % | AH2: Δ MV(d.)+FAC % - Δ M % | AI2: Δ MV(d.)+FAC % - Δ M % | AJ2: Δ MV(d.)+FAC % - Δ V % | AK2: test | AL2: match? | AM2: M_FAC | AN2: V_FAC
A3: 1781 | G3: =J3/B3 -> #DIV/0! | H3: =G3-G2 -> #DIV/0! | I3: =H3-H2 -> #DIV/0! | K3: =J3-J2 -> #VALUE! | L3: =(K3-K2)/K2 -> #VALUE! | M3: =L3-I3 -> #VALUE! | U3: =S3*Y3 -> #DIV/0! | W3: =S3/B3 -> #DIV/0! | Y3: =J3/S3 -> #DIV/0! | AA3: =W3*Y3 -> #DIV/0! | AD3: =J3-AA3 -> #DIV/0! | AE3: =AA3+AD3 -> #DIV/0! | AG3: =AF3-I3 -> #DIV/0! | AH3: =AF3-T4 -> #DIV/0! | AI3: =AF3-X3 -> 0 | AJ3: =AF3-Z3 -> 0
A4: 1782 | C4: =IF(B4>B3,"inflation",IF(B4<B3,"deflation","stable")) -> stable | D4: =IFERROR(IF(I4>0,"expansive","contractive"),"") | E4: =IF(AND(C4="inflation",D4="expansive"),"inflationary expansion",IF(AND(C4="inflation",D4="contractive"),"stagflation",IF(AND(C4="deflation",D4="expansive"),"deflationary growth",IF(AND(C4="deflation",D4="contractive"),"recession",0)))) -> 0 | F4: =(B4-B3)/B3 -> #DIV/0! | G4: =J4/B4 -> #DIV/0! | H4: =G4-G3 -> #DIV/0! | I4: =H4/G3 -> #DIV/0! | K4: =J4-J3 -> 0 | L4: =K4/J3 -> #DIV/0! | M4: =L4-I4 -> #DIV/0! | N4: =IF(L4>I4, "inflation",IF(L4<I4, "deflation","stable")) -> #DIV/0! | O4: =IFERROR(IF(N4=C4,1,0),"") | P4: =M4-F4 -> #DIV/0! | Q4: =J4-J3 -> 0 | R4: =Q4/J3 -> #DIV/0! | T4: =(S4-S3)/S3 -> #DIV/0! | U4: =S4*Y4 -> #DIV/0! | V4: =(U4-U3)/U3 -> #DIV/0! | W4: =S4/B4 -> #DIV/0! | X4: =(W4-W3)/W3 -> #DIV/0! | Y4: =J4/S4 -> #DIV/0! | Z4: =(Y4-Y3)/Y3 -> #DIV/0! | AA4: =W4*Y4 -> #DIV/0! | AB4: =AA4-AA3 -> #DIV/0! | AC4: =AB4/AA3 -> #DIV/0! | AD4: =J4-AA4 -> #DIV/0! | AE4: =AA4+AD4 -> #DIV/0! | AF4: =(AE4-AE3)/AE3 -> #DIV/0! | AG4: =AF4-I4 -> #DIV/0! | AH4: =AF4-T5 -> #DIV/0! | AI4: =AF4-X4 -> #DIV/0! | AJ4: =AF4-Z4 -> #DIV/0! | AK4: =IF(AG4>0, "inflation",IF(AG4<0,"deflation","stable")) -> #DIV/0! | AL4: =IFERROR(IF(AK4=C4,1,0),"") | AM4: =AD4/AN4 -> #DIV/0! | AN4: =Y4 -> #DIV/0!
A5: 1783 | C5: =IF(B5>B4,"inflation",IF(B5<B4,"deflation","stable")) -> stable | D5: =IF(I5>0,"expansive","contractive") -> #DIV/0! | E5: =IF(AND(C5="inflation",D5="expansive"),"inflationary expansion",IF(AND(C5="inflation",D5="contractive"),"stagflation",IF(AND(C5="deflation",D5="expansive"),"deflationary growth",IF(AND(C5="deflation",D5="contractive"),"recession",0)))) -> #DIV/0! | F5: =(B5-B4)/B4 -> #DIV/0! | G5: =J5/B5 -> #DIV/0! | H5: =G5-G4 -> #DIV/0! | I5: =H5/G4 -> #DIV/0! | K5: =J5-J4 -> 0 | L5: =K5/J4 -> #DIV/0! | M5: =L5-I5 -> #DIV/0! | N5: =IF(L5>I5, "inflation",IF(L5<I5, "deflation","stable")) -> #DIV/0! | O5: =IFERROR(IF(N5=C5,1,0),"") | P5: =M5-F5 -> #DIV/0! | Q5: =J5-J4 -> 0 | R5: =Q5/J4 -> #DIV/0! | T5: =(S5-S4)/S4 -> #DIV/0! | U5: =S5*Y5 -> #DIV/0! | V5: =(U5-U4)/U4 -> #DIV/0! | W5: =S5/B5 -> #DIV/0! | X5: =(W5-W4)/W4 -> #DIV/0! | Y5: =J5/S5 -> #DIV/0! | Z5: =(Y5-Y4)/Y4 -> #DIV/0! | AA5: =W5*Y5 -> #DIV/0! | AB5: =AA5-AA4 -> #DIV/0! | AC5: =AB5/AA4 -> #DIV/0! | AD5: =J5-AA5 -> #DIV/0! | AE5: =AA5+AD5 -> #DIV/0! | AF5: =(AE5-AE4)/AE4 -> #DIV/0! | AG5: =AF5-I5 -> #DIV/0! | AH5: =AF5-T6 -> #DIV/0! | AI5: =AF5-X5 -> #DIV/0! | AJ5: =AF5-Z5 -> #DIV/0! | AK5: =IF(AG5>0, "inflation",IF(AG5<0,"deflation","stable")) -> #DIV/0! | AL5: =IFERROR(IF(AK5=C5,1,0),"") | AM5: =AD5/AN5 -> #DIV/0! | AN5: =Y5 -> #DIV/0!
A6: 1784 | C6: =IF(B6>B5,"inflation",IF(B6<B5,"deflation","stable")) -> stable | D6: =IF(I6>0,"expansive","contractive") -> #DIV/0! | E6: =IF(AND(C6="inflation",D6="expansive"),"inflationary expansion",IF(AND(C6="inflation",D6="contractive"),"stagflation",IF(AND(C6="deflation",D6="expansive"),"deflationary growth",IF(AND(C6="deflation",D6="contractive"),"recession",0)))) -> #DIV/0! | F6: =(B6-B5)/B5 -> #DIV/0! | G6: =J6/B6 -> #DIV/0! | H6: =G6-G5 -> #DIV/0! | I6: =H6/G5 -> #DIV/0! | K6: =J6-J5 -> 0 | L6: =K6/J5 -> #DIV/0! | M6: =L6-I6 -> #DIV/0! | N6: =IF(L6>I6, "inflation",IF(L6<I6, "deflation","stable")) -> #DIV/0! | O6: =IFERROR(IF(N6=C6,1,0),"") | P6: =M6-F6 -> #DIV/0! | Q6: =J6-J5 -> 0 | R6: =Q6/J5 -> #DIV/0! | T6: =(S6-S5)/S5 -> #DIV/0! | U6: =S6*Y6 -> #DIV/0! | V6: =(U6-U5)/U5 -> #DIV/0! | W6: =S6/B6 -> #DIV/0! | X6: =(W6-W5)/W5 -> #DIV/0! | Y6: =J6/S6 -> #DIV/0! | Z6: =(Y6-Y5)/Y5 -> #DIV/0! | AA6: =W6*Y6 -> #DIV/0! | AB6: =AA6-AA5 -> #DIV/0! | AC6: =AB6/AA5 -> #DIV/0! | AD6: =J6-AA6 -> #DIV/0! | AE6: =AA6+AD6 -> #DIV/0! | AF6: =(AE6-AE5)/AE5 -> #DIV/0! | AG6: =AF6-I6 -> #DIV/0! | AH6: =AF6-T7 -> #DIV/0! | AI6: =AF6-X6 -> #DIV/0! | AJ6: =AF6-Z6 -> #DIV/0! | AK6: =IF(AG6>0, "inflation",IF(AG6<0,"deflation","stable")) -> #DIV/0! | AL6: =IFERROR(IF(AK6=C6,1,0),"") | AM6: =AD6/AN6 -> #DIV/0! | AN6: =Y6 -> #DIV/0!
A7: 1785 | C7: =IF(B7>B6,"inflation",IF(B7<B6,"deflation","stable")) -> stable | D7: =IF(I7>0,"expansive","contractive") -> #DIV/0! | E7: =IF(AND(C7="inflation",D7="expansive"),"inflationary expansion",IF(AND(C7="inflation",D7="contractive"),"stagflation",IF(AND(C7="deflation",D7="expansive"),"deflationary growth",IF(AND(C7="deflation",D7="contractive"),"recession",0)))) -> #DIV/0! | F7: =(B7-B6)/B6 -> #DIV/0! | G7: =J7/B7 -> #DIV/0! | H7: =G7-G6 -> #DIV/0! | I7: =H7/G6 -> #DIV/0! | K7: =J7-J6 -> 0 | L7: =K7/J6 -> #DIV/0! | M7: =L7-I7 -> #DIV/0! | N7: =IF(L7>I7, "inflation",IF(L7<I7, "deflation","stable")) -> #DIV/0! | O7: =IFERROR(IF(N7=C7,1,0),"") | P7: =M7-F7 -> #DIV/0! | Q7: =J7-J6 -> 0 | R7: =Q7/J6 -> #DIV/0! | T7: =(S7-S6)/S6 -> #DIV/0! | U7: =S7*Y7 -> #DIV/0! | V7: =(U7-U6)/U6 -> #DIV/0! | W7: =S7/B7 -> #DIV/0! | X7: =(W7-W6)/W6 -> #DIV/0! | Y7: =J7/S7 -> #DIV/0! | Z7: =(Y7-Y6)/Y6 -> #DIV/0! | AA7: =W7*Y7 -> #DIV/0! | AB7: =AA7-AA6 -> #DIV/0! | AC7: =AB7/AA6 -> #DIV/0! | AD7: =J7-AA7 -> #DIV/0! | AE7: =AA7+AD7 -> #DIV/0! | AF7: =(AE7-AE6)/AE6 -> #DIV/0! | AG7: =AF7-I7 -> #DIV/0! | AH7: =AF7-T8 -> #DIV/0! | AI7: =AF7-X7 -> #DIV/0! | AJ7: =AF7-Z7 -> #DIV/0! | AK7: =IF(AG7>0, "inflation",IF(AG7<0,"deflation","stable")) -> #DIV/0! | AL7: =IFERROR(IF(AK7=C7,1,0),"") | AM7: =AD7/AN7 -> #DIV/0! | AN7: =Y7 -> #DIV/0!
A8: 1786 | C8: =IF(B8>B7,"inflation",IF(B8<B7,"deflation","stable")) -> stable | D8: =IF(I8>0,"expansive","contractive") -> #DIV/0! | E8: =IF(AND(C8="inflation",D8="expansive"),"inflationary expansion",IF(AND(C8="inflation",D8="contractive"),"stagflation",IF(AND(C8="deflation",D8="expansive"),"deflationary growth",IF(AND(C8="deflation",D8="contractive"),"recession",0)))) -> #DIV/0! | F8: =(B8-B7)/B7 -> #DIV/0! | G8: =J8/B8 -> #DIV/0! | H8: =G8-G7 -> #DIV/0! | I8: =H8/G7 -> #DIV/0! | K8: =J8-J7 -> 0 | L8: =K8/J7 -> #DIV/0! | M8: =L8-I8 -> #DIV/0! | N8: =IF(L8>I8, "inflation",IF(L8<I8, "deflation","stable")) -> #DIV/0! | O8: =IFERROR(IF(N8=C8,1,0),"") | P8: =M8-F8 -> #DIV/0! | Q8: =J8-J7 -> 0 | R8: =Q8/J7 -> #DIV/0! | T8: =(S8-S7)/S7 -> #DIV/0! | U8: =S8*Y8 -> #DIV/0! | V8: =(U8-U7)/U7 -> #DIV/0! | W8: =S8/B8 -> #DIV/0! | X8: =(W8-W7)/W7 -> #DIV/0! | Y8: =J8/S8 -> #DIV/0! | Z8: =(Y8-Y7)/Y7 -> #DIV/0! | AA8: =W8*Y8 -> #DIV/0! | AB8: =AA8-AA7 -> #DIV/0! | AC8: =AB8/AA7 -> #DIV/0! | AD8: =J8-AA8 -> #DIV/0! | AE8: =AA8+AD8 -> #DIV/0! | AF8: =(AE8-AE7)/AE7 -> #DIV/0! | AG8: =AF8-I8 -> #DIV/0! | AH8: =AF8-T9 -> #DIV/0! | AI8: =AF8-X8 -> #DIV/0! | AJ8: =AF8-Z8 -> #DIV/0! | AK8: =IF(AG8>0, "inflation",IF(AG8<0,"deflation","stable")) -> #DIV/0! | AL8: =IFERROR(IF(AK8=C8,1,0),"") | AM8: =AD8/AN8 -> #DIV/0! | AN8: =Y8 -> #DIV/0!
A9: 1787 | C9: =IF(B9>B8,"inflation",IF(B9<B8,"deflation","stable")) -> stable | D9: =IF(I9>0,"expansive","contractive") -> #DIV/0! | E9: =IF(AND(C9="inflation",D9="expansive"),"inflationary expansion",IF(AND(C9="inflation",D9="contractive"),"stagflation",IF(AND(C9="deflation",D9="expansive"),"deflationary growth",IF(AND(C9="deflation",D9="contractive"),"recession",0)))) -> #DIV/0! | F9: =(B9-B8)/B8 -> #DIV/0! | G9: =J9/B9 -> #DIV/0! | H9: =G9-G8 -> #DIV/0! | I9: =H9/G8 -> #DIV/0! | K9: =J9-J8 -> 0 | L9: =K9/J8 -> #DIV/0! | M9: =L9-I9 -> #DIV/0! | N9: =IF(L9>I9, "inflation",IF(L9<I9, "deflation","stable")) -> #DIV/0! | O9: =IFERROR(IF(N9=C9,1,0),"") | P9: =M9-F9 -> #DIV/0! | Q9: =J9-J8 -> 0 | R9: =Q9/J8 -> #DIV/0! | T9: =(S9-S8)/S8 -> #DIV/0! | U9: =S9*Y9 -> #DIV/0! | V9: =(U9-U8)/U8 -> #DIV/0! | W9: =S9/B9 -> #DIV/0! | X9: =(W9-W8)/W8 -> #DIV/0! | Y9: =J9/S9 -> #DIV/0! | Z9: =(Y9-Y8)/Y8 -> #DIV/0! | AA9: =W9*Y9 -> #DIV/0! | AB9: =AA9-AA8 -> #DIV/0! | AC9: =AB9/AA8 -> #DIV/0! | AD9: =J9-AA9 -> #DIV/0! | AE9: =AA9+AD9 -> #DIV/0! | AF9: =(AE9-AE8)/AE8 -> #DIV/0! | AG9: =AF9-I9 -> #DIV/0! | AH9: =AF9-T10 -> #DIV/0! | AI9: =AF9-X9 -> #DIV/0! | AJ9: =AF9-Z9 -> #DIV/0! | AK9: =IF(AG9>0, "inflation",IF(AG9<0,"deflation","stable")) -> #DIV/0! | AL9: =IFERROR(IF(AK9=C9,1,0),"") | AM9: =AD9/AN9 -> #DIV/0! | AN9: =Y9 -> #DIV/0!
A10: 1788 | C10: =IF(B10>B9,"inflation",IF(B10<B9,"deflation","stable")) -> stable | D10: =IF(I10>0,"expansive","contractive") -> #DIV/0! | E10: =IF(AND(C10="inflation",D10="expansive"),"inflationary expansion",IF(AND(C10="inflation",D10="contractive"),"stagflation",IF(AND(C10="deflation",D10="expansive"),"deflationary growth",IF(AND(C10="deflation",D10="contractive"),"recession",0)))) -> #DIV/0! | F10: =(B10-B9)/B9 -> #DIV/0! | G10: =J10/B10 -> #DIV/0! | H10: =G10-G9 -> #DIV/0! | I10: =H10/G9 -> #DIV/0! | K10: =J10-J9 -> 0 | L10: =K10/J9 -> #DIV/0! | M10: =L10-I10 -> #DIV/0! | N10: =IF(L10>I10, "inflation",IF(L10<I10, "deflation","stable")) -> #DIV/0! | O10: =IFERROR(IF(N10=C10,1,0),"") | P10: =M10-F10 -> #DIV/0! | Q10: =J10-J9 -> 0 | R10: =Q10/J9 -> #DIV/0! | T10: =(S10-S9)/S9 -> #DIV/0! | U10: =S10*Y10 -> #DIV/0! | V10: =(U10-U9)/U9 -> #DIV/0! | W10: =S10/B10 -> #DIV/0! | X10: =(W10-W9)/W9 -> #DIV/0! | Y10: =J10/S10 -> #DIV/0! | Z10: =(Y10-Y9)/Y9 -> #DIV/0! | AA10: =W10*Y10 -> #DIV/0! | AB10: =AA10-AA9 -> #DIV/0! | AC10: =AB10/AA9 -> #DIV/0! | AD10: =J10-AA10 -> #DIV/0! | AE10: =AA10+AD10 -> #DIV/0! | AF10: =(AE10-AE9)/AE9 -> #DIV/0! | AG10: =AF10-I10 -> #DIV/0! | AH10: =AF10-T11 -> #DIV/0! | AI10: =AF10-X10 -> #DIV/0! | AJ10: =AF10-Z10 -> #DIV/0! | AK10: =IF(AG10>0, "inflation",IF(AG10<0,"deflation","stable")) -> #DIV/0! | AL10: =IFERROR(IF(AK10=C10,1,0),"") | AM10: =AD10/AN10 -> #DIV/0! | AN10: =Y10 -> #DIV/0!
A11: 1789 | C11: =IF(B11>B10,"inflation",IF(B11<B10,"deflation","stable")) -> stable | D11: =IF(I11>0,"expansive","contractive") -> #DIV/0! | E11: =IF(AND(C11="inflation",D11="expansive"),"inflationary expansion",IF(AND(C11="inflation",D11="contractive"),"stagflation",IF(AND(C11="deflation",D11="expansive"),"deflationary growth",IF(AND(C11="deflation",D11="contractive"),"recession",0)))) -> #DIV/0! | F11: =(B11-B10)/B10 -> #DIV/0! | G11: =J11/B11 -> #DIV/0! | H11: =G11-G10 -> #DIV/0! | I11: =H11/G10 -> #DIV/0! | K11: =J11-J10 -> 0 | L11: =K11/J10 -> #DIV/0! | M11: =L11-I11 -> #DIV/0! | N11: =IF(L11>I11, "inflation",IF(L11<I11, "deflation","stable")) -> #DIV/0! | O11: =IFERROR(IF(N11=C11,1,0),"") | P11: =M11-F11 -> #DIV/0! | Q11: =J11-J10 -> 0 | R11: =Q11/J10 -> #DIV/0! | T11: =(S11-S10)/S10 -> #DIV/0! | U11: =S11*Y11 -> #DIV/0! | V11: =(U11-U10)/U10 -> #DIV/0! | W11: =S11/B11 -> #DIV/0! | X11: =(W11-W10)/W10 -> #DIV/0! | Y11: =J11/S11 -> #DIV/0! | Z11: =(Y11-Y10)/Y10 -> #DIV/0! | AA11: =W11*Y11 -> #DIV/0! | AB11: =AA11-AA10 -> #DIV/0! | AC11: =AB11/AA10 -> #DIV/0! | AD11: =J11-AA11 -> #DIV/0! | AE11: =AA11+AD11 -> #DIV/0! | AF11: =(AE11-AE10)/AE10 -> #DIV/0! | AG11: =AF11-I11 -> #DIV/0! | AH11: =AF11-T12 -> #DIV/0! | AI11: =AF11-X11 -> #DIV/0! | AJ11: =AF11-Z11 -> #DIV/0! | AK11: =IF(AG11>0, "inflation",IF(AG11<0,"deflation","stable")) -> #DIV/0! | AL11: =IFERROR(IF(AK11=C11,1,0),"") | AM11: =AD11/AN11 -> #DIV/0! | AN11: =Y11 -> #DIV/0!
A12: 1790 | B12: 1 | C12: =IF(B12>B11,"inflation",IF(B12<B11,"deflation","stable")) -> inflation | D12: =IF(I12>0,"expansive","contractive") -> #DIV/0! | E12: =IF(AND(C12="inflation",D12="expansive"),"inflationary expansion",IF(AND(C12="inflation",D12="contractive"),"stagflation",IF(AND(C12="deflation",D12="expansive"),"deflationary growth",IF(AND(C12="deflation",D12="contractive"),"recession",0)))) -> #DIV/0! | F12: =(B12-B11)/B11 -> #DIV/0! | G12: =J12/B12 -> 0.19289785 | H12: =G12-G11 -> #DIV/0! | I12: =H12/G11 -> #DIV/0! | J12: 0.19289785 | K12: =J12-J11 -> 0.19289785 | L12: =K12/J11 -> #DIV/0! | M12: =L12-I12 -> #DIV/0! | N12: =IF(L12>I12, "inflation",IF(L12<I12, "deflation","stable")) -> #DIV/0! | O12: =IFERROR(IF(N12=C12,1,0),"") | P12: =M12-F12 -> #DIV/0! | Q12: =J12-J11 -> 0.19289785 | R12: =Q12/J11 -> #DIV/0! | T12: =(S12-S11)/S11 -> #DIV/0! | U12: =S12*Y12 -> #DIV/0! | V12: =(U12-U11)/U11 -> #DIV/0! | W12: =S12/B12 -> 0 | X12: =(W12-W11)/W11 -> #DIV/0! | Y12: =J12/S12 -> #DIV/0! | Z12: =(Y12-Y11)/Y11 -> #DIV/0! | AA12: =W12*Y12 -> #DIV/0! | AB12: =AA12-AA11 -> #DIV/0! | AC12: =AB12/AA11 -> #DIV/0! | AD12: =J12-AA12 -> #DIV/0! | AE12: =AA12+AD12 -> #DIV/0! | AF12: =(AE12-AE11)/AE11 -> #DIV/0! | AG12: =AF12-I12 -> #DIV/0! | AH12: =AF12-T13 -> #DIV/0! | AI12: =AF12-X12 -> #DIV/0! | AJ12: =AF12-Z12 -> #DIV/0! | AK12: =IF(AG12>0, "inflation",IF(AG12<0,"deflation","stable")) -> #DIV/0! | AL12: =IFERROR(IF(AK12=C12,1,0),"") | AM12: =AD12/AN12 -> #DIV/0! | AN12: =Y12 -> #DIV/0!
A13: 1791 | B13: 1.0272727 | C13: =IF(B13>B12,"inflation",IF(B13<B12,"deflation","stable")) -> inflation | D13: =IF(I13>0,"expansive","contractive") -> expansive | E13: =IF(AND(C13="inflation",D13="expansive"),"inflationary expansion",IF(AND(C13="inflation",D13="contractive"),"stagflation",IF(AND(C13="deflation",D13="expansive"),"deflationary growth",IF(AND(C13="deflation",D13="contractive"),"recession",0)))) -> inflationary expansion | F13: =(B13-B12)/B12 -> 0.027272727 | G13: =J13/B13 -> 0.20448798 | H13: =G13-G12 -> 0.011590128 | I13: =H13/G12 -> 0.060084275 | J13: 0.21006493 | K13: =J13-J12 -> 0.017167073 | L13: =K13/J12 -> 0.088995664 | M13: =L13-I13 -> 0.028911389 | N13: =IF(L13>I13, "inflation",IF(L13<I13, "deflation","stable")) -> inflation | O13: =IFERROR(IF(N13=C13,1,0),"") -> 1 | P13: =M13-F13 -> 0.001638662 | Q13: =J13-J12 -> 0.017167073 | R13: =Q13/J12 -> 0.088995664 | T13: =(S13-S12)/S12 -> #DIV/0! | U13: =S13*Y13 -> #DIV/0! | V13: =(U13-U12)/U12 -> #DIV/0! | W13: =S13/B13 -> 0 | X13: =(W13-W12)/W12 -> #DIV/0! | Y13: =J13/S13 -> #DIV/0! | Z13: =(Y13-Y12)/Y12 -> #DIV/0! | AA13: =W13*Y13 -> #DIV/0! | AB13: =AA13-AA12 -> #DIV/0! | AC13: =AB13/AA12 -> #DIV/0! | AD13: =J13-AA13 -> #DIV/0! | AE13: =AA13+AD13 -> #DIV/0! | AF13: =(AE13-AE12)/AE12 -> #DIV/0! | AG13: =AF13-I13 -> #DIV/0! | AH13: =AF13-T14 -> #DIV/0! | AI13: =AF13-X13 -> #DIV/0! | AJ13: =AF13-Z13 -> #DIV/0! | AK13: =IF(AG13>0, "inflation",IF(AG13<0,"deflation","stable")) -> #DIV/0! | AL13: =IFERROR(IF(AK13=C13,1,0),"") | AM13: =AD13/AN13 -> #DIV/0! | AN13: =Y13 -> #DIV/0!
A14: 1792 | B14: 1.0454545 | C14: =IF(B14>B13,"inflation",IF(B14<B13,"deflation","stable")) -> inflation | D14: =IF(I14>0,"expansive","contractive") -> expansive | E14: =IF(AND(C14="inflation",D14="expansive"),"inflationary expansion",IF(AND(C14="inflation",D14="contractive"),"stagflation",IF(AND(C14="deflation",D14="expansive"),"deflationary growth",IF(AND(C14="deflation",D14="contractive"),"recession",0)))) -> inflationary expansion | F14: =(B14-B13)/B13 -> 0.017699115 | G14: =J14/B14 -> 0.21955966 | H14: =G14-G13 -> 0.015071681 | I14: =H14/G13 -> 0.073704482 | J14: 0.22953965 | K14: =J14-J13 -> 0.01947472 | L14: =K14/J13 -> 0.092708101 | M14: =L14-I14 -> 0.019003619 | N14: =IF(L14>I14, "inflation",IF(L14<I14, "deflation","stable")) -> inflation | O14: =IFERROR(IF(N14=C14,1,0),"") -> 1 | P14: =M14-F14 -> 0.0013045041 | Q14: =J14-J13 -> 0.01947472 | R14: =Q14/J13 -> 0.092708101 | T14: =(S14-S13)/S13 -> #DIV/0! | U14: =S14*Y14 -> #DIV/0! | V14: =(U14-U13)/U13 -> #DIV/0! | W14: =S14/B14 -> 0 | X14: =(W14-W13)/W13 -> #DIV/0! | Y14: =J14/S14 -> #DIV/0! | Z14: =(Y14-Y13)/Y13 -> #DIV/0! | AA14: =W14*Y14 -> #DIV/0! | AB14: =AA14-AA13 -> #DIV/0! | AC14: =AB14/AA13 -> #DIV/0! | AD14: =J14-AA14 -> #DIV/0! | AE14: =AA14+AD14 -> #DIV/0! | AF14: =(AE14-AE13)/AE13 -> #DIV/0! | AG14: =AF14-I14 -> #DIV/0! | AH14: =AF14-T15 -> #DIV/0! | AI14: =AF14-X14 -> #DIV/0! | AJ14: =AF14-Z14 -> #DIV/0! | AK14: =IF(AG14>0, "inflation",IF(AG14<0,"deflation","stable")) -> #DIV/0! | AL14: =IFERROR(IF(AK14=C14,1,0),"") | AM14: =AD14/AN14 -> #DIV/0! | AN14: =Y14 -> #DIV/0!
A15: 1793 | B15: 1.0818182 | C15: =IF(B15>B14,"inflation",IF(B15<B14,"deflation","stable")) -> inflation | D15: =IF(I15>0,"expansive","contractive") -> expansive | E15: =IF(AND(C15="inflation",D15="expansive"),"inflationary expansion",IF(AND(C15="inflation",D15="contractive"),"stagflation",IF(AND(C15="deflation",D15="expansive"),"deflationary growth",IF(AND(C15="deflation",D15="contractive"),"recession",0)))) -> inflationary expansion | F15: =(B15-B14)/B14 -> 0.034782609 | G15: =J15/B15 -> 0.23700405 | H15: =G15-G14 -> 0.017444385 | I15: =H15/G14 -> 0.079451686 | J15: 0.25639529 | K15: =J15-J14 -> 0.026855641 | L15: =K15/J14 -> 0.11699783 | M15: =L15-I15 -> 0.037546146 | N15: =IF(L15>I15, "inflation",IF(L15<I15, "deflation","stable")) -> inflation | O15: =IFERROR(IF(N15=C15,1,0),"") -> 1 | P15: =M15-F15 -> 0.0027635369 | Q15: =J15-J14 -> 0.026855641 | R15: =Q15/J14 -> 0.11699783 | T15: =(S15-S14)/S14 -> #DIV/0! | U15: =S15*Y15 -> #DIV/0! | V15: =(U15-U14)/U14 -> #DIV/0! | W15: =S15/B15 -> 0 | X15: =(W15-W14)/W14 -> #DIV/0! | Y15: =J15/S15 -> #DIV/0! | Z15: =(Y15-Y14)/Y14 -> #DIV/0! | AA15: =W15*Y15 -> #DIV/0! | AB15: =AA15-AA14 -> #DIV/0! | AC15: =AB15/AA14 -> #DIV/0! | AD15: =J15-AA15 -> #DIV/0! | AE15: =AA15+AD15 -> #DIV/0! | AF15: =(AE15-AE14)/AE14 -> #DIV/0! | AG15: =AF15-I15 -> #DIV/0! | AH15: =AF15-T16 -> #DIV/0! | AI15: =AF15-X15 -> #DIV/0! | AJ15: =AF15-Z15 -> #DIV/0! | AK15: =IF(AG15>0, "inflation",IF(AG15<0,"deflation","stable")) -> #DIV/0! | AL15: =IFERROR(IF(AK15=C15,1,0),"") | AM15: =AD15/AN15 -> #DIV/0! | AN15: =Y15 -> #DIV/0!
A16: 1794 | B16: 1.2 | C16: =IF(B16>B15,"inflation",IF(B16<B15,"deflation","stable")) -> inflation | D16: =IF(I16>0,"expansive","contractive") -> expansive | E16: =IF(AND(C16="inflation",D16="expansive"),"inflationary expansion",IF(AND(C16="inflation",D16="contractive"),"stagflation",IF(AND(C16="deflation",D16="expansive"),"deflationary growth",IF(AND(C16="deflation",D16="contractive"),"recession",0)))) -> inflationary expansion | F16: =(B16-B15)/B15 -> 0.1092437 | G16: =J16/B16 -> 0.26773939 | H16: =G16-G15 -> 0.030735341 | I16: =H16/G15 -> 0.12968277 | J16: 0.32128727 | K16: =J16-J15 -> 0.064891979 | L16: =K16/J15 -> 0.25309349 | M16: =L16-I16 -> 0.12341072 | N16: =IF(L16>I16, "inflation",IF(L16<I16, "deflation","stable")) -> inflation | O16: =IFERROR(IF(N16=C16,1,0),"") -> 1 | P16: =M16-F16 -> 0.014167025 | Q16: =J16-J15 -> 0.064891979 | R16: =Q16/J15 -> 0.25309349 | T16: =(S16-S15)/S15 -> #DIV/0! | U16: =S16*Y16 -> #DIV/0! | V16: =(U16-U15)/U15 -> #DIV/0! | W16: =S16/B16 -> 0 | X16: =(W16-W15)/W15 -> #DIV/0! | Y16: =J16/S16 -> #DIV/0! | Z16: =(Y16-Y15)/Y15 -> #DIV/0! | AA16: =W16*Y16 -> #DIV/0! | AB16: =AA16-AA15 -> #DIV/0! | AC16: =AB16/AA15 -> #DIV/0! | AD16: =J16-AA16 -> #DIV/0! | AE16: =AA16+AD16 -> #DIV/0! | AF16: =(AE16-AE15)/AE15 -> #DIV/0! | AG16: =AF16-I16 -> #DIV/0! | AH16: =AF16-T17 -> #DIV/0! | AI16: =AF16-X16 -> #DIV/0! | AJ16: =AF16-Z16 -> #DIV/0! | AK16: =IF(AG16>0, "inflation",IF(AG16<0,"deflation","stable")) -> #DIV/0! | AL16: =IFERROR(IF(AK16=C16,1,0),"") | AM16: =AD16/AN16 -> #DIV/0! | AN16: =Y16 -> #DIV/0!
A17: 1795 | B17: 1.3727273 | C17: =IF(B17>B16,"inflation",IF(B17<B16,"deflation","stable")) -> inflation | D17: =IF(I17>0,"expansive","contractive") -> expansive | E17: =IF(AND(C17="inflation",D17="expansive"),"inflationary expansion",IF(AND(C17="inflation",D17="contractive"),"stagflation",IF(AND(C17="deflation",D17="expansive"),"deflationary growth",IF(AND(C17="deflation",D17="contractive"),"recession",0)))) -> inflationary expansion | F17: =(B17-B16)/B16 -> 0.14393939 | G17: =J17/B17 -> 0.28425703 | H17: =G17-G16 -> 0.016517646 | I17: =H17/G16 -> 0.061692998 | J17: 0.39020738 | K17: =J17-J16 -> 0.068920117 | L17: =K17/J16 -> 0.21451245 | M17: =L17-I17 -> 0.15281945 | N17: =IF(L17>I17, "inflation",IF(L17<I17, "deflation","stable")) -> inflation | O17: =IFERROR(IF(N17=C17,1,0),"") -> 1 | P17: =M17-F17 -> 0.0088800528 | Q17: =J17-J16 -> 0.068920117 | R17: =Q17/J16 -> 0.21451245 | T17: =(S17-S16)/S16 -> #DIV/0! | U17: =S17*Y17 -> #DIV/0! | V17: =(U17-U16)/U16 -> #DIV/0! | W17: =S17/B17 -> 0 | X17: =(W17-W16)/W16 -> #DIV/0! | Y17: =J17/S17 -> #DIV/0! | Z17: =(Y17-Y16)/Y16 -> #DIV/0! | AA17: =W17*Y17 -> #DIV/0! | AB17: =AA17-AA16 -> #DIV/0! | AC17: =AB17/AA16 -> #DIV/0! | AD17: =J17-AA17 -> #DIV/0! | AE17: =AA17+AD17 -> #DIV/0! | AF17: =(AE17-AE16)/AE16 -> #DIV/0! | AG17: =AF17-I17 -> #DIV/0! | AH17: =AF17-T18 -> #DIV/0! | AI17: =AF17-X17 -> #DIV/0! | AJ17: =AF17-Z17 -> #DIV/0! | AK17: =IF(AG17>0, "inflation",IF(AG17<0,"deflation","stable")) -> #DIV/0! | AL17: =IFERROR(IF(AK17=C17,1,0),"") | AM17: =AD17/AN17 -> #DIV/0! | AN17: =Y17 -> #DIV/0!
A18: 1796 | B18: 1.4454545 | C18: =IF(B18>B17,"inflation",IF(B18<B17,"deflation","stable")) -> inflation | D18: =IF(I18>0,"expansive","contractive") -> expansive | E18: =IF(AND(C18="inflation",D18="expansive"),"inflationary expansion",IF(AND(C18="inflation",D18="contractive"),"stagflation",IF(AND(C18="deflation",D18="expansive"),"deflationary growth",IF(AND(C18="deflation",D18="contractive"),"recession",0)))) -> inflationary expansion | F18: =(B18-B17)/B17 -> 0.052980132 | G18: =J18/B18 -> 0.29283567 | H18: =G18-G17 -> 0.0085786341 | I18: =H18/G17 -> 0.030179144 | J18: 0.42328065 | K18: =J18-J17 -> 0.033073265 | L18: =K18/J17 -> 0.084758172 | M18: =L18-I18 -> 0.054579028 | N18: =IF(L18>I18, "inflation",IF(L18<I18, "deflation","stable")) -> inflation | O18: =IFERROR(IF(N18=C18,1,0),"") -> 1 | P18: =M18-F18 -> 0.0015988951 | Q18: =J18-J17 -> 0.033073265 | R18: =Q18/J17 -> 0.084758172 | T18: =(S18-S17)/S17 -> #DIV/0! | U18: =S18*Y18 -> #DIV/0! | V18: =(U18-U17)/U17 -> #DIV/0! | W18: =S18/B18 -> 0 | X18: =(W18-W17)/W17 -> #DIV/0! | Y18: =J18/S18 -> #DIV/0! | Z18: =(Y18-Y17)/Y17 -> #DIV/0! | AA18: =W18*Y18 -> #DIV/0! | AB18: =AA18-AA17 -> #DIV/0! | AC18: =AB18/AA17 -> #DIV/0! | AD18: =J18-AA18 -> #DIV/0! | AE18: =AA18+AD18 -> #DIV/0! | AF18: =(AE18-AE17)/AE17 -> #DIV/0! | AG18: =AF18-I18 -> #DIV/0! | AH18: =AF18-T19 -> #DIV/0! | AI18: =AF18-X18 -> #DIV/0! | AJ18: =AF18-Z18 -> #DIV/0! | AK18: =IF(AG18>0, "inflation",IF(AG18<0,"deflation","stable")) -> #DIV/0! | AL18: =IFERROR(IF(AK18=C18,1,0),"") | AM18: =AD18/AN18 -> #DIV/0! | AN18: =Y18 -> #DIV/0!
A19: 1797 | B19: 1.3909091 | C19: =IF(B19>B18,"inflation",IF(B19<B18,"deflation","stable")) -> deflation | D19: =IF(I19>0,"expansive","contractive") -> expansive | E19: =IF(AND(C19="inflation",D19="expansive"),"inflationary expansion",IF(AND(C19="inflation",D19="contractive"),"stagflation",IF(AND(C19="deflation",D19="expansive"),"deflationary growth",IF(AND(C19="deflation",D19="contractive"),"recession",0)))) -> deflationary growth | F19: =(B19-B18)/B18 -> -0.037735849 | G19: =J19/B19 -> 0.29824088 | H19: =G19-G18 -> 0.0054052131 | I19: =H19/G18 -> 0.018458179 | J19: 0.41482595 | K19: =J19-J18 -> -0.0084546946 | L19: =K19/J18 -> -0.019974205 | M19: =L19-I19 -> -0.038432384 | N19: =IF(L19>I19, "inflation",IF(L19<I19, "deflation","stable")) -> deflation | O19: =IFERROR(IF(N19=C19,1,0),"") -> 1 | P19: =M19-F19 -> -0.00069653504 | Q19: =J19-J18 -> -0.0084546946 | R19: =Q19/J18 -> -0.019974205 | T19: =(S19-S18)/S18 -> #DIV/0! | U19: =S19*Y19 -> #DIV/0! | V19: =(U19-U18)/U18 -> #DIV/0! | W19: =S19/B19 -> 0 | X19: =(W19-W18)/W18 -> #DIV/0! | Y19: =J19/S19 -> #DIV/0! | Z19: =(Y19-Y18)/Y18 -> #DIV/0! | AA19: =W19*Y19 -> #DIV/0! | AB19: =AA19-AA18 -> #DIV/0! | AC19: =AB19/AA18 -> #DIV/0! | AD19: =J19-AA19 -> #DIV/0! | AE19: =AA19+AD19 -> #DIV/0! | AF19: =(AE19-AE18)/AE18 -> #DIV/0! | AG19: =AF19-I19 -> #DIV/0! | AH19: =AF19-T20 -> #DIV/0! | AI19: =AF19-X19 -> #DIV/0! | AJ19: =AF19-Z19 -> #DIV/0! | AK19: =IF(AG19>0, "inflation",IF(AG19<0,"deflation","stable")) -> #DIV/0! | AL19: =IFERROR(IF(AK19=C19,1,0),"") | AM19: =AD19/AN19 -> #DIV/0! | AN19: =Y19 -> #DIV/0!
A20: 1798 | B20: 1.3454545 | C20: =IF(B20>B19,"inflation",IF(B20<B19,"deflation","stable")) -> deflation | D20: =IF(I20>0,"expansive","contractive") -> expansive | E20: =IF(AND(C20="inflation",D20="expansive"),"inflationary expansion",IF(AND(C20="inflation",D20="contractive"),"stagflation",IF(AND(C20="deflation",D20="expansive"),"deflationary growth",IF(AND(C20="deflation",D20="contractive"),"recession",0)))) -> deflationary growth | F20: =(B20-B19)/B19 -> -0.032679739 | G20: =J20/B20 -> 0.31054937 | H20: =G20-G19 -> 0.012308485 | I20: =H20/G19 -> 0.041270282 | J20: 0.41783006 | K20: =J20-J19 -> 0.003004104 | L20: =K20/J19 -> 0.0072418419 | M20: =L20-I20 -> -0.034028441 | N20: =IF(L20>I20, "inflation",IF(L20<I20, "deflation","stable")) -> deflation | O20: =IFERROR(IF(N20=C20,1,0),"") -> 1 | P20: =M20-F20 -> -0.001348702 | Q20: =J20-J19 -> 0.003004104 | R20: =Q20/J19 -> 0.0072418419 | T20: =(S20-S19)/S19 -> #DIV/0! | U20: =S20*Y20 -> #DIV/0! | V20: =(U20-U19)/U19 -> #DIV/0! | W20: =S20/B20 -> 0 | X20: =(W20-W19)/W19 -> #DIV/0! | Y20: =J20/S20 -> #DIV/0! | Z20: =(Y20-Y19)/Y19 -> #DIV/0! | AA20: =W20*Y20 -> #DIV/0! | AB20: =AA20-AA19 -> #DIV/0! | AC20: =AB20/AA19 -> #DIV/0! | AD20: =J20-AA20 -> #DIV/0! | AE20: =AA20+AD20 -> #DIV/0! | AF20: =(AE20-AE19)/AE19 -> #DIV/0! | AG20: =AF20-I20 -> #DIV/0! | AH20: =AF20-T21 -> #DIV/0! | AI20: =AF20-X20 -> #DIV/0! | AJ20: =AF20-Z20 -> #DIV/0! | AK20: =IF(AG20>0, "inflation",IF(AG20<0,"deflation","stable")) -> #DIV/0! | AL20: =IFERROR(IF(AK20=C20,1,0),"") | AM20: =AD20/AN20 -> #DIV/0! | AN20: =Y20 -> #DIV/0!
A21: 1799 | B21: 1.3454545 | C21: =IF(B21>B20,"inflation",IF(B21<B20,"deflation","stable")) -> stable | D21: =IF(I21>0,"expansive","contractive") -> expansive | E21: =IF(AND(C21="inflation",D21="expansive"),"inflationary expansion",IF(AND(C21="inflation",D21="contractive"),"stagflation",IF(AND(C21="deflation",D21="expansive"),"deflationary growth",IF(AND(C21="deflation",D21="contractive"),"recession",0)))) -> 0 | F21: =(B21-B20)/B20 -> 0 | G21: =J21/B21 -> 0.33193739 | H21: =G21-G20 -> 0.021388026 | I21: =H21/G20 -> 0.068871581 | J21: 0.44660667 | K21: =J21-J20 -> 0.028776617 | L21: =K21/J20 -> 0.068871581 | M21: =L21-I21 -> 0 | N21: =IF(L21>I21, "inflation",IF(L21<I21, "deflation","stable")) -> inflation | O21: =IFERROR(IF(N21=C21,1,0),"") -> 0 | P21: =M21-F21 -> 0 | Q21: =J21-J20 -> 0.028776617 | R21: =Q21/J20 -> 0.068871581 | T21: =(S21-S20)/S20 -> #DIV/0! | U21: =S21*Y21 -> #DIV/0! | V21: =(U21-U20)/U20 -> #DIV/0! | W21: =S21/B21 -> 0 | X21: =(W21-W20)/W20 -> #DIV/0! | Y21: =J21/S21 -> #DIV/0! | Z21: =(Y21-Y20)/Y20 -> #DIV/0! | AA21: =W21*Y21 -> #DIV/0! | AB21: =AA21-AA20 -> #DIV/0! | AC21: =AB21/AA20 -> #DIV/0! | AD21: =J21-AA21 -> #DIV/0! | AE21: =AA21+AD21 -> #DIV/0! | AF21: =(AE21-AE20)/AE20 -> #DIV/0! | AG21: =AF21-I21 -> #DIV/0! | AH21: =AF21-T22 -> #DIV/0! | AI21: =AF21-X21 -> #DIV/0! | AJ21: =AF21-Z21 -> #DIV/0! | AK21: =IF(AG21>0, "inflation",IF(AG21<0,"deflation","stable")) -> #DIV/0! | AL21: =IFERROR(IF(AK21=C21,1,0),"") | AM21: =AD21/AN21 -> #DIV/0! | AN21: =Y21 -> #DIV/0!
A22: 1800 | B22: 1.3837977 | C22: =IF(B22>B21,"inflation",IF(B22<B21,"deflation","stable")) -> inflation | D22: =IF(I22>0,"expansive","contractive") -> expansive | E22: =IF(AND(C22="inflation",D22="expansive"),"inflationary expansion",IF(AND(C22="inflation",D22="contractive"),"stagflation",IF(AND(C22="deflation",D22="expansive"),"deflationary growth",IF(AND(C22="deflation",D22="contractive"),"recession",0)))) -> inflationary expansion | F22: =(B22-B21)/B21 -> 0.028498256 | G22: =J22/B22 -> 0.35084877 | H22: =G22-G21 -> 0.018911375 | I22: =H22/G21 -> 0.056972716 | J22: 0.4855037 | K22: =J22-J21 -> 0.038897027 | L22: =K22/J21 -> 0.087094595 | M22: =L22-I22 -> 0.030121879 | N22: =IF(L22>I22, "inflation",IF(L22<I22, "deflation","stable")) -> inflation | O22: =IFERROR(IF(N22=C22,1,0),"") -> 1 | P22: =M22-F22 -> 0.0016236231 | Q22: =J22-J21 -> 0.038897027 | R22: =Q22/J21 -> 0.087094595 | S22: 0.028 | T22: =(S22-S21)/S21 -> #DIV/0! | U22: =S22*Y22 -> 0.4855037 | V22: =(U22-U21)/U21 -> #DIV/0! | W22: =S22/B22 -> 0.020234172 | X22: =(W22-W21)/W21 -> #DIV/0! | Y22: =J22/S22 -> 17.339418 | Z22: =(Y22-Y21)/Y21 -> #DIV/0! | AA22: =W22*Y22 -> 0.35084877 | AB22: =AA22-AA21 -> #DIV/0! | AC22: =AB22/AA21 -> #DIV/0! | AD22: =J22-AA22 -> 0.13465493 | AE22: =AA22+AD22 -> 0.4855037 | AF22: =(AE22-AE21)/AE21 -> #DIV/0! | AG22: =AF22-I22 -> #DIV/0! | AH22: =AF22-T23 -> #DIV/0! | AI22: =AF22-X22 -> #DIV/0! | AJ22: =AF22-Z22 -> #DIV/0! | AK22: =IF(AG22>0, "inflation",IF(AG22<0,"deflation","stable")) -> #DIV/0! | AL22: =IFERROR(IF(AK22=C22,1,0),"") | AM22: =AD22/AN22 -> 0.0077658278 | AN22: =Y22 -> 17.339418
A23: 1801 | B23: 1.4133431 | C23: =IF(B23>B22,"inflation",IF(B23<B22,"deflation","stable")) -> inflation | D23: =IF(I23>0,"expansive","contractive") -> expansive | E23: =IF(AND(C23="inflation",D23="expansive"),"inflationary expansion",IF(AND(C23="inflation",D23="contractive"),"stagflation",IF(AND(C23="deflation",D23="expansive"),"deflationary growth",IF(AND(C23="deflation",D23="contractive"),"recession",0)))) -> inflationary expansion | F23: =(B23-B22)/B22 -> 0.021350993 | G23: =J23/B23 -> 0.36794688 | H23: =G23-G22 -> 0.017098107 | I23: =H23/G22 -> 0.048733554 | J23: 0.52003518 | K23: =J23-J22 -> 0.034531479 | L23: =K23/J22 -> 0.071125057 | M23: =L23-I23 -> 0.022391503 | N23: =IF(L23>I23, "inflation",IF(L23<I23, "deflation","stable")) -> inflation | O23: =IFERROR(IF(N23=C23,1,0),"") -> 1 | P23: =M23-F23 -> 0.0010405098 | Q23: =J23-J22 -> 0.034531479 | R23: =Q23/J22 -> 0.071125057 | S23: 0 | T23: =(S23-S22)/S22 -> -1 | U23: =S23*Y23 -> #DIV/0! | V23: =(U23-U22)/U22 -> #DIV/0! | W23: =S23/B23 -> 0 | X23: =(W23-W22)/W22 -> -1 | Y23: =J23/S23 -> #DIV/0! | Z23: =(Y23-Y22)/Y22 -> #DIV/0! | AA23: =W23*Y23 -> #DIV/0! | AB23: =AA23-AA22 -> #DIV/0! | AC23: =AB23/AA22 -> #DIV/0! | AD23: =J23-AA23 -> #DIV/0! | AE23: =AA23+AD23 -> #DIV/0! | AF23: =(AE23-AE22)/AE22 -> #DIV/0! | AG23: =AF23-I23 -> #DIV/0! | AH23: =AF23-T24 -> #DIV/0! | AI23: =AF23-X23 -> #DIV/0! | AJ23: =AF23-Z23 -> #DIV/0! | AK23: =IF(AG23>0, "inflation",IF(AG23<0,"deflation","stable")) -> #DIV/0! | AL23: =IFERROR(IF(AK23=C23,1,0),"") | AM23: =AD23/AN23 -> #DIV/0! | AN23: =Y23 -> #DIV/0!
A24: 1802 | B24: 1.2010997 | C24: =IF(B24>B23,"inflation",IF(B24<B23,"deflation","stable")) -> deflation | D24: =IF(I24>0,"expansive","contractive") -> expansive | E24: =IF(AND(C24="inflation",D24="expansive"),"inflationary expansion",IF(AND(C24="inflation",D24="contractive"),"stagflation",IF(AND(C24="deflation",D24="expansive"),"deflationary growth",IF(AND(C24="deflation",D24="contractive"),"recession",0)))) -> deflationary growth | F24: =(B24-B23)/B23 -> -0.15017118 | G24: =J24/B24 -> 0.37951843 | H24: =G24-G23 -> 0.011571554 | I24: =H24/G23 -> 0.031448979 | J24: 0.45583947 | K24: =J24-J23 -> -0.064195707 | L24: =K24/J23 -> -0.12344493 | M24: =L24-I24 -> -0.15489391 | N24: =IF(L24>I24, "inflation",IF(L24<I24, "deflation","stable")) -> deflation | O24: =IFERROR(IF(N24=C24,1,0),"") -> 1 | P24: =M24-F24 -> -0.0047227303 | Q24: =J24-J23 -> -0.064195707 | R24: =Q24/J23 -> -0.12344493 | S24: 0 | T24: =(S24-S23)/S23 -> #DIV/0! | U24: =S24*Y24 -> #DIV/0! | V24: =(U24-U23)/U23 -> #DIV/0! | W24: =S24/B24 -> 0 | X24: =(W24-W23)/W23 -> #DIV/0! | Y24: =J24/S24 -> #DIV/0! | Z24: =(Y24-Y23)/Y23 -> #DIV/0! | AA24: =W24*Y24 -> #DIV/0! | AB24: =AA24-AA23 -> #DIV/0! | AC24: =AB24/AA23 -> #DIV/0! | AD24: =J24-AA24 -> #DIV/0! | AE24: =AA24+AD24 -> #DIV/0! | AF24: =(AE24-AE23)/AE23 -> #DIV/0! | AG24: =AF24-I24 -> #DIV/0! | AH24: =AF24-T25 -> #DIV/0! | AI24: =AF24-X24 -> #DIV/0! | AJ24: =AF24-Z24 -> #DIV/0! | AK24: =IF(AG24>0, "inflation",IF(AG24<0,"deflation","stable")) -> #DIV/0! | AL24: =IFERROR(IF(AK24=C24,1,0),"") | AM24: =AD24/AN24 -> #DIV/0! | AN24: =Y24 -> #DIV/0!
